<robot name="example_robot">
    <!-- Enlace pasivo 0 -->
    <link name="link0_passive">
        <visual>
            <material name="blue">
                <color rgba="0 0 .8 1"/>
            </material>
            <geometry>
                <origin xyz="0 0 0" rpy="0 0 0"/>
                <cylinder length="0.5" radius="0.05"/>
            </geometry>
        </visual>
    </link>

    <!-- Enlace eje X 0 -->
    <link name="link0_x_axis">
        <visual>
            <material name="red">
                <color rgba="1 0 0 1"/>
            </material>
            <geometry>
                <origin xyz="0 0 0" rpy="0 0 0"/>
                <cylinder length="0.5" radius="0.05"/>
            </geometry>
        </visual>
    </link>

    <!-- Articulación entre link0_passive y link0_x_axis -->
    <joint name="q0_x" type="revolute">
        <origin xyz="0 0 0" rpy="0 1.571 0"/>
        <parent link="link0_passive"/>
        <child link="link0_x_axis"/>
        <axis xyz="0 0 1"/>
    </joint>

    <!-- Enlace 1 -->
    <link name="link1">
        <visual>
            <material name="blue">
                <color rgba="0 0 .8 1"/>
            </material>
            <geometry>
                <origin xyz="0 0 0" rpy="0 0 0"/>
                <cylinder length="0.5" radius="0.05"/>
            </geometry>
        </visual>
    </link>

    <!-- Enlace eje X 1 -->
    <link name="link1_x_axis">
        <visual>
            <origin xyz="0 0 0.25" rpy="0 0 0"/>
            <material name="red"/>
            <geometry>
                <cylinder length="0.5" radius="0.05"/>
            </geometry>
        </visual>
    </link>

    <!-- Articulación entre link0_passive y link1 -->
    <joint name="q1" type="revolute">
        <origin xyz="0 0 0.9" rpy="0 0 0"/>
        <parent link="link0_passive"/>
        <child link="link1"/>
        <axis xyz="0 0 1"/>
    </joint>

    <!-- Articulación fija entre link1 y link1_passive -->
    <joint name="q1_passive" type="fixed">
        <origin xyz="0 0 0" rpy="1.5707963267948966 0 0"/>
        <parent link="link1"/>
        <child link="link1_passive"/>
    </joint>

    <!-- Enlace pasivo 1 -->
    <link name="link1_passive">
        <visual>
            <origin xyz="0 0 0.25" rpy="0 0 0"/>
            <material name="blue"/>
            <geometry>
                <cylinder length="0.5" radius="0.05"/>
            </geometry>
        </visual>
    </link>

    <!-- Articulación fija entre link1_passive y link1_x_axis -->
    <joint name="q1_x" type="fixed">
        <origin xyz="0 0 0" rpy="0 1.571 0"/>
        <parent link="link1_passive"/>
        <child link="link1_x_axis"/>
    </joint>

    <!-- Enlace 2 -->
    <link name="link2">
        <visual>
            <material name="blue">
                <color rgba="0 0 .8 1"/>
            </material>
            <geometry>
                <origin xyz="0 0 0" rpy="0 0 0"/>
                <cylinder length="0.5" radius="0.05"/>
            </geometry>
        </visual>
    </link>

    <!-- Enlace eje X 2 -->
    <link name="link2_x_axis">
        <visual>
            <origin xyz="0 0 0.25" rpy="0 0 0"/>
            <material name="red"/>
            <geometry>
                <cylinder length="0.5" radius="0.05"/>
            </geometry>
        </visual>
    </link>

    <!-- Articulación entre link1_passive y link2 -->
    <joint name="q2" type="revolute">
        <origin xyz="0 0 0" rpy="0 0 0"/>
        <parent link="link1_passive"/>
        <child link="link2"/>
        <axis xyz="0 0 1"/>
    </joint>

    <!-- Articulación fija entre link2 y link2_passive -->
    <joint name="q2_passive" type="fixed">
        <origin xyz="0.6 0 0" rpy="0 0 0"/>
        <parent link="link2"/>
        <child link="link2_passive"/>
    </joint>

    <!-- Enlace pasivo 2 -->
    <link name="link2_passive">
        <visual>
            <origin xyz="0 0 0.25" rpy="0 0 0"/>
            <material name="blue"/>
            <geometry>
                <cylinder length="0.5" radius="0.05"/>
            </geometry>
        </visual>
    </link>

    <!-- Articulación fija entre link2_passive y link2_x_axis -->
    <joint name="q2_x" type="fixed">
        <origin xyz="0 0 0" rpy="0 1.571 0"/>
        <parent link="link2_passive"/>
        <child link="link2_x_axis"/>
    </joint>

    <!-- Enlace 3 -->
    <link name="link3">
        <visual>
            <material name="blue">
                <color rgba="0 0 .8 1"/>
            </material>
            <geometry>
                <origin xyz="0 0 0" rpy="0 0 0"/>
                <cylinder length="0.5" radius="0.05"/>
            </geometry>
        </visual>
    </link>

    <!-- Enlace eje X 3 -->
    <link name="link3_x_axis">
        <visual>
            <origin xyz="0 0 0.25" rpy="0 0 0"/>
            <material name="red"/>
            <geometry>
                <cylinder length="0.5" radius="0.05"/>
            </geometry>
        </visual>
    </link>

    <!-- Articulación entre link2_passive y link3 -->
    <joint name="q3" type="revolute">
        <origin xyz="0 0 0" rpy="0 0 0"/>
        <parent link="link2_passive"/>
        <child link="link3"/>
        <axis xyz="0 0 1"/>
    </joint>

    <!-- Articulación fija entre link3 y link3_passive -->
    <joint name="q3_passive" type="fixed">
        <origin xyz="0.5 0 0" rpy="0 0 0"/>
        <parent link="link3"/>
        <child link="link3_passive"/>
    </joint>

    <!-- Enlace pasivo 3 -->
    <link name="link3_passive">
        <visual>
            <origin xyz="0 0 0.25" rpy="0 0 0"/>
            <material name="blue"/>
            <geometry>
                <cylinder length="0.5" radius="0.05"/>
            </geometry>
        </visual>
    </link>

    <!-- Articulación fija entre link3_passive y link3_x_axis -->
    <joint name="q3_x" type="fixed">
        <origin xyz="0 0 0" rpy="0 1.571 0"/>
        <parent link="link3_passive"/>
        <child link="link3_x_axis"/>
    </joint>

    <!-- Enlace 4 -->
    <link name="link4">
        <visual>
            <material name="blue">
                <color rgba="0 0 .8 1"/>
            </material>
            <geometry>
                <origin xyz="0 0 0" rpy="0 0 0"/>
                <cylinder length="0.5" radius="0.05"/>
            </geometry>
        </visual>
    </link>

    <!-- Enlace eje X 4 -->
    <link name="link4_x_axis">
        <visual>
            <origin xyz="0 0 0.25" rpy="0 0 0"/>
            <material name="red"/>
            <geometry>
                <cylinder length="0.5" radius="0.05"/>
            </geometry>
        </visual>
    </link>

    <!-- Articulación entre link3_passive y link4 -->
    <joint name="q4" type="revolute">
        <origin xyz="0 0 0" rpy="0 0 0"/>
        <parent link="link3_passive"/>
        <child link="link4"/>
        <axis xyz="0 0 1"/>
    </joint>

    <!-- Articulación fija entre link4 y link4_passive -->
    <joint name="q4_passive" type="fixed">
        <origin xyz="0.4 0 0" rpy="0 0 0"/>
        <parent link="link4"/>
        <child link="link4_passive"/>
    </joint>

    <!-- Enlace pasivo 4 -->
    <link name="link4_passive">
        <visual>
            <origin xyz="0 0 0.25" rpy="0 0 0"/>
            <material name="blue"/>
            <geometry>
                <cylinder length="0.5" radius="0.05"/>
            </geometry>
        </visual>
    </link>

    <!-- Articulación fija entre link4_passive y link4_x_axis -->
    <joint name="q4_x" type="fixed">
        <origin xyz="0 0 0" rpy="0 1.571 0"/>
        <parent link="link4_passive"/>
        <child link="link4_x_axis"/>
    </joint>
</robot>